<TestLog><Error file="test_boost.cpp" line="12"><![CDATA[check 2 * 3 == 5 failed]]></Error><Exception file="unknown location" line="0"><![CDATA[std::runtime_error: unexpected exception]]><LastCheckpoint file="test_boost.cpp" line="12"><![CDATA[]]></LastCheckpoint></Exception></TestLog><TestResult><TestSuite name="MyTest" result="failed" assertions_passed="1" assertions_failed="2" expected_failures="0" test_cases_passed="1" test_cases_failed="2" test_cases_skipped="0" test_cases_aborted="1"></TestSuite></TestResult>