<?xml version="1.0" encoding="UTF-8"?>
<testsuites tests="3" failures="2" disabled="0" errors="0" timestamp="2014-08-09T18:20:29" time="0.002" name="AllTests">
  <testsuite name="FooTest" tests="3" failures="2" disabled="0" errors="0" time="0.001">
    <testcase name="test_success" status="run" time="0" classname="FooTest" />
    <testcase name="test_failure" status="run" time="0.001" classname="FooTest">
      <failure message="test_gtest.cpp:43&#x0A;Value of: 5&#x0A;Expected: 2 * 3&#x0A;Which is: 6" type=""><![CDATA[test_gtest.cpp:43
Value of: 5
Expected: 2 * 3
Which is: 6]]></failure>
    </testcase>
    <testcase name="test_error" status="run" time="0" classname="FooTest">
      <failure message="unknown file&#x0A;C++ exception with description &quot;unexpected exception&quot; thrown in the test body." type=""><![CDATA[unknown file
C++ exception with description "unexpected exception" thrown in the test body.]]></failure>
    </testcase>
  </testsuite>
</testsuites>
